<?xml version="1.0" encoding="utf-8"?>
<mujoco model="sawyer">
   <include file="door_config.xml"></include>
    <worldbody>
        <!--<camera pos="0 0 3.2" name="topview" />-->
        <!-- <light directional="true" cutoff="40" exponent="10" diffuse=".4 .4 .4" specular=".7 .7 .7" pos="0 0 1.5" dir="0 0 -1"/> -->

        <include file="sawyer_xyz_base_door.xml"></include>
        <!--<geom name="tableTop" type="plane" pos="0 0.6 0" size="1. 0.4 0.5" rgba=".6 .6 .5 1" contype="1" conaffinity="1" />-->
        <!--<geom name="tableTop2" type="plane" pos="0.6 0 0" size="0.4 0.4 0.5" rgba=".6 .6 .5 1" contype="1" conaffinity="1" />-->
        <!--<geom name="tableTop3" type="plane" pos="-0.6 0 0" size="0.4 0.4 0.5" rgba=".6 .6 .5 1" contype="1" conaffinity="1" />-->

        <body name="door" pos="0 0.725 -.025">
            <!--quat="0.70711 0 0 0.70711">-->
                <joint name="doorjoint" pos=".21 0 0" axis="0 0 1"
                       type="hinge" limited="true" range="0 0.523599" damping="0.1" armature="0" />
                <geom type="box" pos="0 0 0" size="0.2 0.01 0.2"
                      rgba=".1 .1 .9 1" contype="2" conaffinity="2" />
                <!--front, parallel to door-->
                <geom type="box" pos="-.05 -0.06 0.05" size="0.1085 0.01 0.01" rgba="0 0 0 1" contype="2" conaffinity="2" />
                <!--front-->
                <geom type="box" pos="0.05 -0.03 0.05" size="0.01 0.03 0.01" rgba="0 0 0 1" contype="2" conaffinity="2"/>
                <geom type="box" pos="-0.15 -0.03 0.05" size="0.01 0.03 0.01" rgba="0 0 0 1" contype="2" conaffinity="2"/>
        </body>
    </worldbody>

    <actuator>
        <motor joint="right_j0" ctrlrange="-100.0 100.0" ctrllimited="false"/>
        <motor joint="right_j1" ctrlrange="-100.0 100.0" ctrllimited="false"/>
        <motor joint="right_j2" ctrlrange="-100.0 100.0" ctrllimited="false"/>
        <motor joint="right_j3" ctrlrange="-100.0 100.0" ctrllimited="false"/>
        <motor joint="right_j4" ctrlrange="-100.0 100.0" ctrllimited="false"/>
        <motor joint="right_j5" ctrlrange="-100.0 100.0" ctrllimited="false"/>
        <motor joint="right_j6" ctrlrange="-100.0 100.0" ctrllimited="false"/>
    </actuator>

</mujoco>
