<mujocoinclude>
    <!-- <camera pos="0 0.5 1.5" name="topview" />
    <camera name="custom" pos="-0.677 2.607 1.378" xyaxes="-0.944 -0.330 -0.000 0.176 -0.503 0.847" />
    <camera name="corner" mode="fixed" pos="-1.1 -0.4 0.6" xyaxes="-1 1 0 -0.2 -0.2 -1" />
    <camera name="corner2" fovy="60" mode="fixed" pos="1.3 -0.2 1.1" euler="3.9 2.3 0.6" />
    <camera name="corner3" fovy="45" mode="fixed" pos="0.9 0 1.5" euler="3.5 2.7 1" /> -->

    <!-- rotate left 90 -->
    <body name="base" pos="0 0 0" childclass="sawyer_base" euler="0 0 1.5707963267948966">
        <!-- robot view -->
        <camera mode="fixed" name="robotview" pos="1.0 0 0.4" quat="0.653 0.271 0.271 0.653" />
        <inertial diaginertia="0 0 0" mass="0" pos="0 0 0" />

        <!-- mount attached here -->
        <body name="mount" pos="0 0 0.01">
            <body name="controller_box" pos="0 0 0">
                <inertial diaginertia="1.71363 1.27988 0.809981" mass="46.64" pos="-0.325 0 -0.38" />
                <geom pos="-0.325 0 -0.38" size="0.11 0.2 0.265" type="box"
                    name="controller_box_col"
                    rgba="0.3 0.3 0.3 0" />
            </body>
            <body name="pedestal_feet" pos="0 0 0">
                <inertial diaginertia="8.16095 9.59375 15.0785" mass="167.09" pos="-0.1225 0 -0.758" />
                <geom pos="-0.1225 0 -0.758" size="0.385 0.35 0.155" type="box"
                    name="pedestal_feet_col"
                    rgba="0.3 0.3 0.3 0" />
            </body>
            <body name="torso" pos="0 0 0">
                <inertial diaginertia="1e-08 1e-08 1e-08" mass="0.0001" pos="0 0 0" />
                <geom conaffinity="0" contype="0" group="1" pos="0 0 -0.05" size="0.05 0.05 0.05"
                    type="box" name="torso_vis" rgba="0.2 0.2 0.2 0" />
            </body>
            <body name="pedestal" pos="0 0 0">
                <inertial diaginertia="6.0869 5.81635 4.20915" mass="60.864" pos="0 0 0"
                    quat="0.659267 -0.259505 -0.260945 0.655692" />
                <geom conaffinity="0" contype="0" group="1" mesh="pedestal" type="mesh"
                    name="pedestal_vis" rgba="0.2 0.2 0.2 1" />
                <geom pos="-0.02 0 -0.29" rgba="0.2 0.2 0.2 0" size="0.18 0.31" type="cylinder"
                    name="pedestal_col" />
            </body>
        </body>
        <!-- ============================ -->

        <body name="right_arm_base_link" pos="0 0 0">
            <inertial diaginertia="0.00740351 0.00681776 0.00672942" mass="2.0687"
                pos="-0.0006241 -2.8025e-05 0.065404" quat="-0.209285 0.674441 0.227335 0.670558" />
            <geom mesh="base_0" material="Mtl2.017" type="mesh" contype="0" conaffinity="0"
                group="1" />
            <geom mesh="base_1" material="Mtl1.017" type="mesh" contype="0" conaffinity="0"
                group="1" />

            <geom pos="0 0 0.12" rgba="0.5 0.1 0.1 0" size="0.08 0.12" type="cylinder"
                name="base_col" />
            <body name="right_l0" pos="0 0 0.08">
                <inertial diaginertia="0.0651588 0.0510944 0.0186218" mass="5.3213"
                    pos="0.024366 0.010969 0.14363" quat="0.894823 0.00899958 -0.170275 0.412573" />
                <joint axis="0 0 1" limited="true" name="right_j0" pos="0 0 0"
                    range="-3.0503 3.0503" armature="5.0" />
                <geom mesh="l0_0" material="Mtl7.007" type="mesh" contype="0" conaffinity="0"
                    group="1" />
                <geom mesh="l0_1" material="Mtl6.008" type="mesh" contype="0" conaffinity="0"
                    group="1" />
                <geom mesh="l0_2" material="Mtl5.010" type="mesh" contype="0" conaffinity="0"
                    group="1" />
                <geom mesh="l0_3" material="Mtl4.012" type="mesh" contype="0" conaffinity="0"
                    group="1" />
                <geom mesh="l0_4" material="Mtl3.013" type="mesh" contype="0" conaffinity="0"
                    group="1" />
                <geom mesh="l0_5" material="Mtl2.014" type="mesh" contype="0" conaffinity="0"
                    group="1" />
                <geom mesh="l0_6" material="Mtl1.014" type="mesh" contype="0" conaffinity="0"
                    group="1" />

                <geom pos="0.08 0 0.23" rgba="0.5 0.1 0.1 0" size="0.07" name="link0_collision" />
                <body name="head" pos="0 0 0.2965">
                    <inertial diaginertia="0.0118334 0.00827089 0.00496574" mass="1.5795"
                        pos="0.0053207 -2.6549e-05 0.1021"
                        quat="0.999993 7.08405e-05 -0.00359857 -0.000626247" />
                    <!--Don't
                    want to control the head joint so remove it from the kinematic tree-->
                    <!--<joint
                    axis="0 0 1" limited="true" name="head_pan" pos="0 0 0" range="-5.0952
                    0.9064"/>-->
                    <geom mesh="head_0" material="Mtlb" type="mesh" contype="0" conaffinity="0"
                        group="1" />
                    <geom mesh="head_1" material="Mtla" type="mesh" contype="0" conaffinity="0"
                        group="1" />
                    <geom mesh="head_2" material="Mtl8" type="mesh" contype="0" conaffinity="0"
                        group="1" />
                    <geom mesh="head_3" material="Mtl9" type="mesh" contype="0" conaffinity="0"
                        group="1" />
                    <geom mesh="head_4" material="Mtl7" type="mesh" contype="0" conaffinity="0"
                        group="1" />
                    <geom mesh="head_5" material="Mtl6" type="mesh" contype="0" conaffinity="0"
                        group="1" />
                    <geom mesh="head_6" material="Mtl4" type="mesh" contype="0" conaffinity="0"
                        group="1" />
                    <geom mesh="head_7" material="Mtl2" type="mesh" contype="0" conaffinity="0"
                        group="1" />
                    <geom mesh="head_8" material="Mtl1" type="mesh" contype="0" conaffinity="0"
                        group="1" />
                    <geom mesh="head_9" material="Mtl5" type="mesh" contype="0" conaffinity="0"
                        group="1" />

                    <geom pos="0 0 0.08" rgba="0.5 0.1 0.1 0" size="0.018" name="head_collision" />
                    <body name="screen" pos="0.03 0 0.105" quat="0.5 0.5 0.5 0.5">
                        <inertial diaginertia="1e-08 1e-08 1e-08" mass="0.0001" pos="0 0 0" />
                        <geom rgba="0.2 0.2 0.2 0" size="0.001" name="screen_collision" />
                    </body>
                    <body name="head_camera" pos="0.0228027 0 0.216572"
                        quat="0.342813 -0.618449 0.618449 -0.342813">
                        <inertial diaginertia="0 0 0" mass="0" pos="0.0228027 0 0.216572"
                            quat="0.342813 -0.618449 0.618449 -0.342813" />
                    </body>
                </body>
                <body name="right_torso_itb" pos="-0.055 0 0.22" quat="0.707107 0 -0.707107 0">
                    <inertial diaginertia="1e-08 1e-08 1e-08" mass="0.0001" pos="0 0 0" />
                </body>
                <body name="right_l1" pos="0.081 0.05 0.237" quat="0.5 -0.5 0.5 0.5">
                    <inertial diaginertia="0.0224339 0.0221624 0.0097097" mass="4.505"
                        pos="-0.0030849 -0.026811 0.092521"
                        quat="0.424888 0.891987 0.132364 -0.0794296" />
                    <joint axis="0 0 1" limited="true" name="right_j1" pos="0 0 0"
                        range="-3.8095 2.2736" armature="2.5" />
                    <geom mesh="l1_0" material="Mtl3.003" type="mesh" contype="0" conaffinity="0"
                        group="1" />
                    <geom mesh="l1_1" material="Mtl2.004" type="mesh" contype="0" conaffinity="0"
                        group="1" />
                    <geom mesh="l1_2" material="Mtl1.004" type="mesh" contype="0" conaffinity="0"
                        group="1" />


                    <geom pos="0 0 0.1225" rgba="0.5 0.1 0.1 0" size="0.07" name="link1_collision" />
                    <body name="right_l2" pos="0 -0.14 0.1425" quat="0.707107 0.707107 0 0">
                        <inertial diaginertia="0.0257928 0.025506 0.00292515" mass="1.745"
                            pos="-0.00016044 -0.014967 0.13582"
                            quat="0.707831 -0.0524761 0.0516007 0.702537" />
                        <joint axis="0 0 1" limited="true" name="right_j2" pos="0 0 0"
                            range="-3.0426 3.0426" armature="1.25" />
                        <geom mesh="l2_0" material="Mtl4.003" type="mesh" contype="0"
                            conaffinity="0" group="1" />
                        <geom mesh="l2_1" material="Mtl5.003" type="mesh" contype="0"
                            conaffinity="0" group="1" />
                        <geom mesh="l2_2" material="Mtl3.004" type="mesh" contype="0"
                            conaffinity="0" group="1" />
                        <geom mesh="l2_3" material="Mtl2.005" type="mesh" contype="0"
                            conaffinity="0" group="1" />
                        <geom mesh="l2_4" material="Mtl1.005" type="mesh" contype="0"
                            conaffinity="0" group="1" />

                        <geom pos="0 0 0.08" rgba="0.5 0.1 0.1 0" size="0.06 0.17" type="cylinder"
                            name="link2_collision" />
                        <body name="right_l3" pos="0 -0.042 0.26" quat="0.707107 -0.707107 0 0">
                            <inertial diaginertia="0.0102404 0.0096997 0.00369622" mass="2.5097"
                                pos="-0.0048135 -0.0281 -0.084154"
                                quat="0.902999 0.385391 -0.0880901 0.168247" />
                            <joint axis="0 0 1" limited="true" name="right_j3" pos="0 0 0"
                                range="-3.0439 3.0439" armature="1.0" />
                            <geom mesh="l3_0" material="Mtl4.005" type="mesh" contype="0"
                                conaffinity="0" group="1" />
                            <geom mesh="l3_1" material="Mtl3.006" type="mesh" contype="0"
                                conaffinity="0" group="1" />
                            <geom mesh="l3_2" material="Mtl2.007" type="mesh" contype="0"
                                conaffinity="0" group="1" />
                            <geom mesh="l3_3" material="Mtl1.007" type="mesh" contype="0"
                                conaffinity="0" group="1" />

                            <geom pos="0 -0.01 -0.12" rgba="0.5 0.1 0.1 0" size="0.06"
                                name="link3_collision" />
                            <body name="right_l4" pos="0 -0.125 -0.1265"
                                quat="0.707107 0.707107 0 0">
                                <inertial diaginertia="0.0136549 0.0135493 0.00127353" mass="1.1136"
                                    pos="-0.0018844 0.0069001 0.1341"
                                    quat="0.803612 0.031257 -0.0298334 0.593582" />
                                <joint axis="0 0 1" limited="true" name="right_j4" pos="0 0 0"
                                    range="-2.9761 2.9761" armature="0.8333" />
                                <geom mesh="l4_0" material="Mtl8.002" type="mesh" contype="0"
                                    conaffinity="0" group="1" />
                                <geom mesh="l4_1" material="Mtl7.004" type="mesh" contype="0"
                                    conaffinity="0" group="1" />
                                <geom mesh="l4_2" material="Mtl6.004" type="mesh" contype="0"
                                    conaffinity="0" group="1" />
                                <geom mesh="l4_3" material="Mtl5.006" type="mesh" contype="0"
                                    conaffinity="0" group="1" />
                                <geom mesh="l4_4" material="Mtl4.008" type="mesh" contype="0"
                                    conaffinity="0" group="1" />
                                <geom mesh="l4_5" material="Mtl3.009" type="mesh" contype="0"
                                    conaffinity="0" group="1" />
                                <geom mesh="l4_6" material="Mtl2.010" type="mesh" contype="0"
                                    conaffinity="0" group="1" />
                                <geom mesh="l4_7" material="Mtl1.010" type="mesh" contype="0"
                                    conaffinity="0" group="1" />

                                <geom pos="0 0 0.11" rgba="0.5 0.1 0.1 0" size="0.045 0.15"
                                    type="cylinder" name="link4_collision" />
                                <body name="right_arm_itb" pos="-0.055 0 0.075"
                                    quat="0.707107 0 -0.707107 0">
                                    <inertial diaginertia="1e-08 1e-08 1e-08" mass="0.0001"
                                        pos="0 0 0" />
                                </body>
                                <body name="right_l5" pos="0 0.031 0.275"
                                    quat="0.707107 -0.707107 0 0">
                                    <inertial diaginertia="0.00474131 0.00422857 0.00190672"
                                        mass="1.5625" pos="0.0061133 -0.023697 0.076416"
                                        quat="0.404076 0.9135 0.0473125 0.00158335" />
                                    <joint axis="0 0 1" limited="true" name="right_j5" pos="0 0 0"
                                        range="-2.9761 2.9761" damping="0.2" armature="0.714" />
                                    <geom mesh="l5_0" material="Mtl5_001" type="mesh" contype="0"
                                        conaffinity="0" group="1" />
                                    <geom mesh="l5_1" material="Mtl4_001" type="mesh" contype="0"
                                        conaffinity="0" group="1" />
                                    <geom mesh="l5_2" material="Mtl2_001" type="mesh" contype="0"
                                        conaffinity="0" group="1" />
                                    <geom mesh="l5_3" material="Mtl1_001" type="mesh" contype="0"
                                        conaffinity="0" group="1" />
                                    <geom mesh="l5_4" material="Mtl3_001" type="mesh" contype="0"
                                        conaffinity="0" group="1" />

                                    <geom pos="0 0 0.1" rgba="0.5 0.1 0.1 0" size="0.06"
                                        name="link5_collision" />
                                    <body name="right_hand_camera" pos="0.039552 -0.033 0.0695"
                                        quat="0.707107 0 0.707107 0">
                                        <inertial diaginertia="0 0 0" mass="0"
                                            pos="0.039552 -0.033 0.0695"
                                            quat="0.707107 0 0.707107 0" />
                                    </body>
                                    <body name="right_wrist" pos="0 0 0.10541"
                                        quat="0.707107 0.707107 0 0">
                                        <inertial diaginertia="0 0 0" mass="0" pos="0 0 0.10541"
                                            quat="0.707107 0.707107 0 0" />
                                    </body>
                                    <body name="right_l6" pos="0 -0.11 0.1053"
                                        quat="0.0616248 0.06163 -0.704416 0.704416">
                                        <inertial diaginertia="0.000360258 0.000311068 0.000214974"
                                            mass="0.3292" pos="-8.0726e-06 0.0085838 -0.0049566"
                                            quat="0.479044 0.515636 -0.513069 0.491322" />
                                        <joint axis="0 0 1" limited="true" name="right_j6"
                                            pos="0 0 0" range="-4.7124 4.7124" damping="0.1"
                                            armature="0.625" />
                                        <geom mesh="l6_0" material="Mtl6.006" type="mesh"
                                            contype="0" conaffinity="0" group="1" />
                                        <geom mesh="l6_1" material="Mtl5.008" type="mesh"
                                            contype="0" conaffinity="0" group="1" />
                                        <geom mesh="l6_2" material="Mtl4.010" type="mesh"
                                            contype="0" conaffinity="0" group="1" />
                                        <geom mesh="l6_3" material="Mtl3.011" type="mesh"
                                            contype="0" conaffinity="0" group="1" />
                                        <geom mesh="l6_4" material="Mtl2.012" type="mesh"
                                            contype="0" conaffinity="0" group="1" />
                                        <geom mesh="l6_5" material="Mtl1.012" type="mesh"
                                            contype="0" conaffinity="0" group="1" />

                                        <geom pos="0 0.015 -0.01" rgba="0.5 0.1 0.1 0"
                                            size="0.055 0.025" type="cylinder"
                                            name="link6_collision" />
                                        <body name="right_hand" pos="0 0 0.024"
                                            quat="0.707105 0 0 0.707108">
                                            <!-- This camera points out from the eef. -->
                                            <camera mode="fixed" name="eye_in_hand" pos="0.05 0 0"
                                                quat="0 0.707108 0.707108 0" fovy="75" />
                                            <!-- To add gripper -->
                                            <body name="gripper_base" pos="0 0 0">
                                                <site name="ft_frame" pos="0 0 0"
                                                    size="0.01 0.01 0.01" rgba="1 0 0 1"
                                                    type="sphere" group="1" />
                                                <inertial pos="0 0 0" quat="-0.5 0.5 0.5 0.5"
                                                    mass="0.3" diaginertia="3e-08 2e-08 2e-08" />
                                                <geom material="Material_001" mesh="connector_plate"
                                                    pos="0 0 0.0018" quat="0.7071068 0 0 0.7071068"
                                                    class="visual" />
                                                <geom mesh="electric_gripper_base_0"
                                                    material="Material_002" pos="0 0 0.0194"
                                                    quat="0.7071068 0 0 0.7071068" class="visual" />
                                                <geom mesh="electric_gripper_base_1"
                                                    material="Material_001.001" pos="0 0 0.0194"
                                                    quat="0.7071068 0 0 0.7071068" class="visual" />

                                                <geom size="0.029 0.05" quat="0 0 0.707107 0.707107"
                                                    type="cylinder" group="0"
                                                    name="gripper_base_col" pos="0.004 0.0 0.04"
                                                    rgba="0.5 0.5 0.5 0" />
                                                <!-- This site was added for visualization. -->
                                                <body name="hand" pos="0 0 0.109"
                                                    quat="0.707105 0 0 -0.707105">
                                                    <site name="grip_site" pos="0 0 0"
                                                        size="0.01 0.01 0.01" rgba="1 0 0 0.5"
                                                        type="sphere" group="1" />
                                                    <site name="ee_x" pos="0.1 0 0" size="0.005 .1"
                                                        quat="0.707105  0 0.707108 0 "
                                                        rgba="1 0 0 0" type="cylinder" group="1" />
                                                    <site name="ee_y" pos="0 0.1 0" size="0.005 .1"
                                                        quat="0.707105 0.707108 0 0" rgba="0 1 0 0"
                                                        type="cylinder" group="1" />
                                                    <site name="ee_z" pos="0 0 0.1" size="0.005 .1"
                                                        quat="1 0 0 0" rgba="0 0 1 0"
                                                        type="cylinder" group="1" />
                                                    <!-- This site was added for visualization. -->
                                                    <site name="grip_site_cylinder" pos="0 0 0"
                                                        size="0.005 10" rgba="0 1 0 0.3"
                                                        type="cylinder" group="1" />
                                                </body>
                                                <body name="l_finger" pos="0 0.01 0.0444">
                                                    <inertial pos="0 0 0" quat="0 0 0 -1"
                                                        mass="0.02" diaginertia="0.01 0.01 0.01" />
                                                    <joint name="l_finger_joint" pos="0 0 0"
                                                        axis="0 1 0" type="slide" limited="true"
                                                        range="-0.0115 0.020833" damping="100"
                                                        armature="1.0" frictionloss="1.0" />
                                                    <geom name="l_finger" quat="0 0 0 -1"
                                                        type="mesh" contype="0" conaffinity="0"
                                                        group="1" mesh="standard_narrow"
                                                        material="finger_mat" />
                                                    <geom size="0.005 0.00675 0.0375"
                                                        pos="0 0.01725 0.04" quat="0 0 0 -1"
                                                        type="box" group="0" conaffinity="1"
                                                        contype="0" name="l_finger_g0"
                                                        friction="0 0 0" rgba="0.5 0.5 0.5 0" />
                                                    <geom size="0.005 0.025 0.0085"
                                                        pos="-0.005 -0.003 0.0083" quat="0 0 0 -1"
                                                        type="box" group="0" conaffinity="1"
                                                        contype="0" name="l_finger_g1"
                                                        friction="0 0 0" rgba="0.5 0.5 0.5 0" />
                                                    <body name="l_finger_tip" pos="0 0.01725 0.075">
                                                        <inertial pos="0 0 0" quat="0 0 0 1"
                                                            mass="0.01" diaginertia="0.01 0.01 0.01" />
                                                        <geom name="l_fingertip_g0_vis"
                                                            quat="0 0 0 1" type="mesh" contype="0"
                                                            conaffinity="1" group="1"
                                                            mesh="half_round_tip"
                                                            material="finger_mat" />

                                                        <geom size="0.004 0.004 0.0185"
                                                            pos="0 -0.0045 -0.015" quat="0 0 0 -1"
                                                            type="box" group="0" conaffinity="1"
                                                            contype="0" name="l_fingertip_g0"
                                                            friction="0 0 0" rgba="0.5 0.5 0.5 0" />
                                                        <geom size="0.0035 0.004 0.0165"
                                                            pos="0 -0.0047 -0.017" type="box"
                                                            conaffinity="1" contype="1"
                                                            name="l_fingerpad_g0" friction="0 0 0"
                                                            rgba="0.5 0.5 0.5 0" />
                                                    </body>
                                                </body>
                                                <body name="r_finger" pos="0 -0.01 0.0444">
                                                    <inertial pos="0 0 0" mass="0.02"
                                                        diaginertia="0.01 0.01 0.01" />
                                                    <joint name="r_finger_joint" pos="0 0 0"
                                                        axis="0 1 0" type="slide" limited="true"
                                                        range="-0.020833 0.0115" damping="100"
                                                        armature="1.0" frictionloss="1.0" />
                                                    <geom name="r_finger" type="mesh" contype="0"
                                                        conaffinity="0" group="1"
                                                        mesh="standard_narrow" material="finger_mat" />
                                                    <geom size="0.005 0.00675 0.0375"
                                                        pos="0 -0.01725 0.04" type="box" group="0"
                                                        conaffinity="1" contype="0"
                                                        name="r_finger_g0" friction="0 0 0"
                                                        rgba="0.5 0.5 0.5 0" />
                                                    <geom size="0.005 0.025 0.0085"
                                                        pos="0.005 0.003 0.0083" type="box"
                                                        group="0" conaffinity="1" contype="0"
                                                        name="r_finger_g1" friction="0 0 0"
                                                        rgba="0.5 0.5 0.5 0" />
                                                    <body name="r_finger_tip" pos="0 -0.01725 0.075">
                                                        <inertial pos="0 0 0" mass="0.01"
                                                            diaginertia="0.01 0.01 0.01" />
                                                        <geom name="r_fingertip_g0_vis" type="mesh"
                                                            contype="0" conaffinity="0" group="1"
                                                            mesh="half_round_tip"
                                                            material="finger_mat" />
                                                        <geom size="0.004 0.004 0.0185"
                                                            pos="0 0.0045 -0.015" type="box"
                                                            group="0" conaffinity="1" contype="0"
                                                            name="r_fingertip_g0" friction="0 0 0"
                                                            rgba="0.5 0.5 0.5 0" />
                                                        <geom size="0.0035 0.004 0.0165"
                                                            pos="0 0.0047 -0.017" type="box"
                                                            conaffinity="1" contype="1"
                                                            name="r_fingerpad_g0" friction="0 0 0"
                                                            rgba="0.5 0.5 0.5 0" />
                                                    </body>
                                                </body>
                                            </body>
                                            <!-- ======================================== -->
                                        </body>
                                    </body>
                                </body>
                                <body name="right_l4_2" pos="0 0 0">
                                    <inertial diaginertia="1e-08 1e-08 1e-08" mass="1e-08"
                                        pos="1e-08 1e-08 1e-08"
                                        quat="0.820473 0.339851 -0.17592 0.424708" />
                                    <geom pos="0 0.01 0.26" size="0.06" name="right_l4_2"
                                        rgba="0.3 0.3 0.3 0" />
                                </body>
                            </body>
                        </body>
                        <body name="right_l2_2" pos="0 0 0">
                            <inertial diaginertia="1e-08 1e-08 1e-08" mass="1e-08"
                                pos="1e-08 1e-08 1e-08" quat="0.820473 0.339851 -0.17592 0.424708" />
                            <geom pos="0 0 0.26" size="0.06" name="right_l2_2" rgba="0.3 0.3 0.3 0" />
                        </body>
                    </body>
                    <body name="right_l1_2" pos="0 0 0">
                        <inertial diaginertia="1e-08 1e-08 1e-08" mass="1e-08"
                            pos="1e-08 1e-08 1e-08" quat="0.820473 0.339851 -0.17592 0.424708" />
                        <geom pos="0 0 0.035" size="0.07 0.07" type="cylinder" name="right_l1_2"
                            rgba="0.3 0.3 0.3 0" />
                    </body>
                </body>
            </body>
        </body>
    </body>
</mujocoinclude>